<robot name="jawpixarm" xmlns:xacro="http://www.ros.org/wiki/xacro">
 
 
 <!-- ============== MESHES =============== -->
  <!-- Base -->
  <link name="base_link">
    <visual>
      <origin xyz="-1.05 1.5 0" rpy="1.5708 0 0"/>
      <geometry>
        <mesh filename="package://jawarm_description/meshes/base.STL" scale="0.01 0.01 0.01"/>
      </geometry>
    </visual>
  </link>

  <!-- Servo1 -->
  <link name="servo1_link">
    <visual>
      <origin xyz="0.05 0.52 0.03" rpy="1.5708 0 0"/>
      <geometry>
        <mesh filename="package://jawarm_description/meshes/servo.STL" scale="0.01 0.01 0.01"/>
      </geometry>
    </visual>
  </link>

  <!-- Phantom link at center of servo1 shaft -->
  <link name="p1_link"/>

  <!-- Base-to-Shoulder -->
  <link name="baseToshoulder_link">
    <visual>
      <origin xyz="-0.2 -0.388 -0.2" rpy="0 0 0"/>
      <geometry>
        <mesh filename="package://jawarm_description/meshes/base_to_shoulder.STL" scale="0.01 0.01 0.01"/>
      </geometry>
    </visual>
  </link>

  <!-- Servo2 --> 
  <link name="servo2_link"> 
    <visual> 
      <origin xyz="-0.17 0.109 0.3" rpy="1.5708 1.5708 0"/> 
      <geometry> 
        <mesh filename="package://jawarm_description/meshes/servo.STL" scale="0.01 0.01 0.01"/> 
      </geometry> 
    </visual> 
  </link>

  <!-- Phantom link at center of servo2 shaft -->
  <link name="p2_link"/>

  <!-- Shoulder --> 
  <link name="shoulder_link"> 
    <visual> 
    <origin xyz="0.11 0.157 0.03" rpy="0 1.5708 3.1415"/> 
      <geometry> 
        <mesh filename="package://jawarm_description/meshes/shoulder.STL" scale="0.01 0.01 0.01"/> 
      </geometry> 
    </visual> 
  </link>

  <!-- Servo3 --> 
  <link name="servo3_link"> 
    <visual> 
      <origin xyz="-1.139 0.431 -0.36" rpy="-1.5708 3.1415 3.1415"/> 
      <geometry> 
        <mesh filename="package://jawarm_description/meshes/servo.STL" scale="0.01 0.01 0.01"/> 
      </geometry> 
    </visual> 
  </link>

  <!-- Phantom link at center of servo3 shaft -->
  <link name="p3_link"/>

  <!-- Elbow --> 
  <link name="elbow_link"> 
    <visual> 
    <origin xyz="0.113 0.148 0.03" rpy="0 1.5708 3.1415"/> 
      <geometry> 
        <mesh filename="package://jawarm_description/meshes/elbow.STL" scale="0.01 0.01 0.01"/> 
      </geometry> 
    </visual> 
  </link>

  <!-- Servo4 --> 
  <link name="servo4_link"> 
    <visual> 
      <origin xyz="-1.38 -0.139 -0.36" rpy="1.5708 0 1.5708"/> 
      <geometry> 
        <mesh filename="package://jawarm_description/meshes/servo.STL" scale="0.01 0.01 0.01"/> 
      </geometry> 
    </visual> 
  </link>

  <!-- Phantom link at center of servo4 shaft -->
  <link name="p4_link"/>

  <!-- Wrist --> 
  <link name="wrist_link"> 
    <visual> 
    <origin xyz="0.1429 -0.2877 0.03" rpy="1.5708 1.5708 3.1415"/> 
      <geometry> 
        <mesh filename="package://jawarm_description/meshes/wrist.STL" scale="0.01 0.01 0.01"/> 
      </geometry> 
    </visual> 
  </link>

  <!-- Servo5 --> 
  <link name="servo5_link"> 
    <visual> 
      <origin xyz="0 -0.01 0" rpy="3.1415 0 0"/> 
      <geometry> 
        <mesh filename="package://jawarm_description/meshes/servo.STL" scale="0.01 0.01 0.01"/> 
      </geometry> 
    </visual> 
  </link>

  <!-- Phantom link at center of servo4 shaft -->
  <link name="p5_link"/>

  <!-- static grip --> 
  <link name="staticgrip_link"> 
    <visual> 
    <origin xyz="0.2 0.335 0" rpy="1.5708 0 4.7123"/> 
      <geometry> 
        <mesh filename="package://jawarm_description/meshes/static_gripper.STL" scale="0.01 0.01 0.01"/> 
      </geometry> 
    </visual> 
  </link>

  <!-- Servo6 --> 
  <link name="servo6_link"> 
    <visual> 
      <origin xyz="-0.0325 0.05 0.03" rpy="1.5708 -1.5708 3.1415"/> 
      <geometry> 
        <mesh filename="package://jawarm_description/meshes/servo.STL" scale="0.01 0.01 0.01"/> 
      </geometry> 
    </visual> 
  </link>

  <!-- Phantom link at center of servo4 shaft -->
  <link name="p6_link"/>

  <!--  mobile grip --> 
  <link name="mobilegrip_link"> 
    <visual> 
    <origin xyz="0.11 -0.4 -0.133" rpy="1.5708 0 3.1415"/> 
      <geometry> 
        <mesh filename="package://jawarm_description/meshes/mobile_gripper.STL" scale="0.01 0.01 0.01"/> 
      </geometry> 
    </visual> 
  </link>



  <!-- ============== JOINTS =============== -->

  <!-- Base -> Servo1 -->
  <joint name="servo1_base" type="fixed">
    <origin xyz="0 0 0" rpy="0 0 0"/>
    <parent link="base_link"/>
    <child link="servo1_link"/>
  </joint>

  <!-- Phantom1 link shaft center -->
  <joint name="p1_to_servo1" type="fixed">
    <origin xyz="0.19 0.41 0.4" rpy="0 0 0"/>
    <parent link="servo1_link"/>
    <child link="p1_link"/>
  </joint>

  <!-- Phantom1 shaft center -> Base-to-shoulder adapter -->
  <joint name="baseToshoulder_to_p1" type="revolute">
    <origin xyz="0 0 0" rpy="0 0 0"/>
    <parent link="p1_link"/>
    <child link="baseToshoulder_link"/>
    <axis xyz="0 0 1"/>
    <limit effort="10" velocity="1.0" lower="-1.57" upper="1.57"/>
  </joint>

  <!-- Servo2 -->
  <joint name="servo2_to_baseToshoulder" type="fixed">
    <origin xyz="0 0 0" rpy="0 0 0"/>
    <parent link="baseToshoulder_link"/>
    <child link="servo2_link"/>
  </joint>

  <!-- Servo2 -> Phantom2 -->
  <joint name="p2_to_servo2" type="fixed">
    <origin xyz="0.19 -0.001 0.155" rpy="0 1.5708 0"/>
    <parent link="servo2_link"/>
    <child link="p2_link"/>
  </joint>

  <!-- Phantom shaft center -> shoulder -->
  <joint name="shoulder_to_p2" type="revolute">
    <origin xyz="0 0 0" rpy="0 0 0"/>
    <parent link="p2_link"/>
    <child link="shoulder_link"/>
    <axis xyz="0 0 1"/>
    <limit effort="10" velocity="1.0" lower="-1.57" upper="1.57"/>
  </joint>

  <!-- Servo3 -->
  <joint name="servo3_to_shoulder" type="fixed">
    <origin xyz="0 0 0" rpy="0 0 0"/>
    <parent link="shoulder_link"/>
    <child link="servo3_link"/>
  </joint>

  <!-- Servo3 -> Phantom3 -->
  <joint name="p3_to_servo3" type="fixed">
    <origin xyz="-1.0 0.32 0" rpy="0 0 0"/>
    <parent link="servo3_link"/>
    <child link="p3_link"/>
  </joint>

  <!-- Phantom shaft center -> elbow -->
  <joint name="elbow_to_p3" type="revolute">
    <origin xyz="0 0 0" rpy="0 0 -1.5708"/>
    <parent link="p3_link"/>
    <child link="elbow_link"/>
    <axis xyz="0 0 1"/>
    <limit effort="10" velocity="1.0" lower="-1.57" upper="1.57"/>
  </joint>

  <!-- Servo4 -->
  <joint name="servo4_to_elbow" type="fixed">
    <origin xyz="0 0 0" rpy="0 0 0"/>
    <parent link="elbow_link"/>
    <child link="servo4_link"/>
  </joint>

  <!-- Servo4 -> Phantom4 -->
  <joint name="p4_to_servo4" type="fixed">
    <origin xyz="-1.268 0.005 0" rpy="0 0 0"/>
    <parent link="servo4_link"/>
    <child link="p4_link"/>
  </joint>

  <!-- Phantom shaft center -> wrist -->
  <joint name="wrist_to_p4" type="revolute">
    <origin xyz="0 0 0" rpy="0 0 -1.5708"/>
    <parent link="p4_link"/>
    <child link="wrist_link"/>
    <axis xyz="0 0 1"/>
    <limit effort="10" velocity="1.0" lower="-1.57" upper="1.57"/>
  </joint>

  <!-- Servo5 -->
  <joint name="servo5_to_wrist" type="fixed">
    <origin xyz="-0.141 -0.28 0" rpy="0 0 0"/>
    <parent link="wrist_link"/>
    <child link="servo5_link"/>
  </joint>

  <!-- Servo5 -> Phantom5 -->
  <joint name="p5_to_servo5" type="fixed">
    <origin xyz="0 0 0" rpy="0 1.5708 0"/>
    <parent link="servo5_link"/>
    <child link="p5_link"/>
  </joint>

  <!-- Phantom shaft center -> wrist -->
  <joint name="staticgrip_to_p5" type="revolute">
    <origin xyz="0.115 -0.38 0.139" rpy="1.5708 1.5708 0"/>
    <parent link="p5_link"/>
    <child link="staticgrip_link"/>
    <axis xyz="0 0 1"/>
    <limit effort="10" velocity="1.0" lower="-1.57" upper="1.57"/>
  </joint>

  <!-- Servo6 -->
  <joint name="servo6_to_staticgrip" type="fixed">
    <origin xyz="-0.141 -0.28 0" rpy="0 0 0"/>
    <parent link="staticgrip_link"/>
    <child link="servo6_link"/>
  </joint>

  <!-- Servo6 -> Phantom6 -->
  <joint name="p6_to_servo6" type="fixed">
    <origin xyz="0 0 0" rpy="3.1415 0 0"/>
    <parent link="servo6_link"/>
    <child link="p6_link"/>
  </joint>

  <!-- Phantom shaft center -> wrist -->
  <joint name="mobilegrip_to_p6" type="revolute">
    <origin xyz="0.335 -0.165 -0.17" rpy="3.1415 6.2831 1.5708"/>
    <parent link="p6_link"/>
    <child link="mobilegrip_link"/>
    <axis xyz="0 1 0"/>
    <limit effort="10" velocity="1.0" lower="-1.57" upper="1.57"/>
  </joint>

</robot>
